Robert (Kobo) May, [31.07.25 16:26]
10:13:41: *========================================*
*running command: ../log-manager/main.exe *
*----------------------------------------*
10:13:48: 2025-07-31 10:13:48,398 - log_manager.gui - INFO - version: 1.6.15
10:13:48: 2025-07-31 10:13:48,399 - log_manager.utils.db_handler - INFO - init DbHandler...
10:13:50: paramiko\client.py:889: UserWarning: Unknown ssh-ed25519 host key for [logs.labfly.de]:2224: b'f099be65f653ff5b74ea1e21a5340ccb'
10:15:27: Connected to logs.labfly.de as diaven.
10:15:27: *exit code: 0*
13:13:09: *========================================*
*running command: ../log-manager/main.exe *
*----------------------------------------*
13:13:22: 2025-07-31 13:13:22,785 - log_manager.gui - INFO - version: 1.6.15
13:13:22: 2025-07-31 13:13:22,786 - log_manager.utils.db_handler - INFO - init DbHandler...
13:13:25: paramiko\client.py:889: UserWarning: Unknown ssh-ed25519 host key for [logs.labfly.de]:2224: b'f099be65f653ff5b74ea1e21a5340ccb'
13:33:24: paramiko\client.py:889: UserWarning: Unknown ssh-ed25519 host key for [logs.labfly.de]:2224: b'f099be65f653ff5b74ea1e21a5340ccb'
13:55:32: paramiko\client.py:889: UserWarning: Unknown ssh-ed25519 host key for [logs.labfly.de]:2224: b'f099be65f653ff5b74ea1e21a5340ccb'
13:56:58: paramiko\client.py:889: UserWarning: Unknown ssh-ed25519 host key for [logs.labfly.de]:2224: b'f099be65f653ff5b74ea1e21a5340ccb'
13:57:12: paramiko\client.py:889: UserWarning: Unknown ssh-ed25519 host key for [logs.labfly.de]:2224: b'f099be65f653ff5b74ea1e21a5340ccb'
15:40:03: paramiko\client.py:889: UserWarning: Unknown ssh-ed25519 host key for [logs.labfly.de]:2224: b'f099be65f653ff5b74ea1e21a5340ccb'
15:40:08: paramiko\client.py:889: UserWarning: Unknown ssh-ed25519 host key for [logs.labfly.de]:2224: b'f099be65f653ff5b74ea1e21a5340ccb'
15:58:28: paramiko\client.py:889: UserWarning: Unknown ssh-ed25519 host key for [logs.labfly.de]:2224: b'f099be65f653ff5b74ea1e21a5340ccb'
16:19:27: Socket exception: Eine vorhandene Verbindung wurde vom Remotehost geschlossen (10054)
16:19:27: Socket exception: Eine vorhandene Verbindung wurde vom Remotehost geschlossen (10054)
Socket exception: Eine vorhandene Verbindung wurde vom Remotehost geschlossen (10054)
Socket exception: Eine vorhandene Verbindung wurde vom Remotehost geschlossen (10054)
Socket exception: Eine vorhandene Verbindung wurde vom Remotehost geschlossen (10054)
Socket exception: Eine vorhandene Verbindung wurde vom Remotehost geschlossen (10054)
Socket exception: Eine vorhandene Verbindung wurde vom Remotehost geschlossen (10054)
Socket exception: Eine vorhandene Verbindung wurde vom Remotehost geschlossen (10054)
16:26:01: 2025-07-31 16:26:01,022 - log_manager.utils.db_handler - ERROR - exception in query_db, query: SELECT id, uid, name FROM vehicle
Traceback (most recent call last):
  File "sqlalchemy\engine\base.py", line 1963, in _exec_single_context
  File "sqlalchemy\engine\default.py", line 943, in do_execute
psycopg2.OperationalError: server closed the connection unexpectedly
  This probably means the server terminated abnormally
  before or while processing the request.
server closed the connection unexpectedly
  This probably means the server terminated abnormally
  before or while processing the request.


The above exception was the direct cause of the following exception:

Traceback (most recent call last):
  File "log_manager\utils\db_handler.py", line 105, in query_db
  File "sqlalchemy\engine\base.py", line 1415, in execute
  File "sqlalchemy\sql\elements.py", line 523, in _execute_on_connection
  File "sqlalchemy\engine\base.py", line 1637, in _execute_clauseelement
  File "sqlalchemy\engine\base.py", line 1842, in _execute_context
  File "sqlalchemy\engine\base.py", line 1982, in _exec_single_context
  File "sqlalchemy\engine\base.py", line 2351, in _handle_dbapi_exception
  File "sqlalchemy\engine\base.py", line 1963, in _exec_single_context
  File "sqlalchemy\engine\default.py", line 943, in do_execute
sqlalchemy.exc.OperationalError: (psycopg2.OperationalError) server closed the connection unexpectedly
  This probably means the server terminated abnormally
  before or while processing the request.
server closed the connection unexpectedly
  This probably means the server terminated abnormally
  before or while processing the request.

[SQL: SELECT id, uid, name FROM vehicle]
(Background on this error at: https://sqlalche.me/e/20/e3q8)
16:26:02: Traceback (most recent call last):
16:26:02: File "pandas\core\indexes\base.py", line 3812, in get_loc
  File "pandas/_libs/index.pyx", line 167, in pandas._libs.index.IndexEngine.get_loc
  File "pandas/_libs/index.pyx", line 196, in pandas._libs.index.IndexEngine.get_loc
  File "pandas/_libs/hashtable_class_helper.pxi", line 7088, in pandas._libs.hashtable.PyObjectHashTable.get_item
  File "pandas/_libs/hashtable_class_helper.pxi", line 7096, in pandas._libs.hashtable.PyObjectHashTable.get_item
KeyError: 'name'

The above exception was the direct cause of the following exception:

Traceback (most recent call last):
  File "main.py", line 56, in <module>
16:26:02: File "log_manager\gui.py", line 670, in main_loop
  File "log_manager\gui.py", line 219, in _load_data_from_db
  File "pandas\core\frame.py", line 4107, in getitem
  File "pandas\core\indexes\base.py", line 3819, in get_loc
KeyError: 'name'
16:26:04: Connected to logs.labfly.de as diaven.
Connected to logs.labfly.de as diaven.
Connected to logs.labfly.de as diaven.
Connected to logs.labfly.de as diaven.
Connected to logs.labfly.de as diaven.
Connected to logs.labfly.de as diaven.
Connected to logs.labfly.de as diaven.
Connected to logs.labfly.de as diaven.
16:26:05: *exit code: 1*
